Workbook
Name ACTION: #REF!
Name Z_2C0D9096_8D85_462A_A9B5_0B488ADB4269_.wvu.Cols: 'FE-01'!$E:$E
Name Z_2C0D9096_8D85_462A_A9B5_0B488ADB4269_.wvu.Cols: 'FE-03'!$E:$E
Name Z_2C0D9096_8D85_462A_A9B5_0B488ADB4269_.wvu.Cols: 'FE-05'!$E:$E
Name Z_2C0D9096_8D85_462A_A9B5_0B488ADB4269_.wvu.Cols: 'FE-06'!$E:$E
Name Z_2C0D9096_8D85_462A_A9B5_0B488ADB4269_.wvu.Cols: 'FE-07'!$E:$E
Name Z_2C0D9096_8D85_462A_A9B5_0B488ADB4269_.wvu.Cols: 'FE-08'!$E:$E
Name Z_2C0D9096_8D85_462A_A9B5_0B488ADB4269_.wvu.Cols: 'FE-09'!$E:$E
Name Z_2C0D9096_8D85_462A_A9B5_0B488ADB4269_.wvu.Cols: 'FE-10'!$E:$E
Name Z_2C0D9096_8D85_462A_A9B5_0B488ADB4269_.wvu.Cols: 'FE-11'!$E:$E
Name Z_2C0D9096_8D85_462A_A9B5_0B488ADB4269_.wvu.Cols: 'FE-12'!$E:$E
Name Z_2C0D9096_8D85_462A_A9B5_0B488ADB4269_.wvu.Cols: 'FE-26'!$E:$E
Name Z_2C0D9096_8D85_462A_A9B5_0B488ADB4269_.wvu.Cols: 'FE-36'!$E:$E
Name Z_2C0D9096_8D85_462A_A9B5_0B488ADB4269_.wvu.Cols: 'FE-43'!$E:$E
Name Z_2C0D9096_8D85_462A_A9B5_0B488ADB4269_.wvu.Cols: 'FE-45'!$E:$E
Name Z_2C0D9096_8D85_462A_A9B5_0B488ADB4269_.wvu.Cols: 'FE-46'!$E:$E
Name Z_2C0D9096_8D85_462A_A9B5_0B488ADB4269_.wvu.Cols: 'FE-47'!$E:$E
Name Z_2C0D9096_8D85_462A_A9B5_0B488ADB4269_.wvu.Cols: 'FE-50'!$E:$E
Name Z_2C0D9096_8D85_462A_A9B5_0B488ADB4269_.wvu.Cols: 'FE-51'!$E:$E
Name Z_2C0D9096_8D85_462A_A9B5_0B488ADB4269_.wvu.Cols: 'FE-52'!$E:$E
Name Z_2C0D9096_8D85_462A_A9B5_0B488ADB4269_.wvu.Cols: 'FE-53'!$E:$E
Name Z_2C0D9096_8D85_462A_A9B5_0B488ADB4269_.wvu.Cols: 'FE-54'!$E:$E
Name Z_2C0D9096_8D85_462A_A9B5_0B488ADB4269_.wvu.Cols: 'FE-55'!$E:$E
Name Z_2C0D9096_8D85_462A_A9B5_0B488ADB4269_.wvu.Cols: 'FE-56'!$E:$E
Name Z_2C0D9096_8D85_462A_A9B5_0B488ADB4269_.wvu.Cols: 'FE-57'!$E:$E
Name Z_2C0D9096_8D85_462A_A9B5_0B488ADB4269_.wvu.Cols: 'FE-58'!$E:$E
Name Z_2C0D9096_8D85_462A_A9B5_0B488ADB4269_.wvu.Cols: 'FE-59'!$E:$E
Name Z_2C0D9096_8D85_462A_A9B5_0B488ADB4269_.wvu.Cols: 'FE-60'!$E:$E
Name Z_2C0D9096_8D85_462A_A9B5_0B488ADB4269_.wvu.Cols: 'FE-61'!$E:$E
Name Z_2C0D9096_8D85_462A_A9B5_0B488ADB4269_.wvu.Cols: 'FE-62'!$E:$E
Name Z_2C0D9096_8D85_462A_A9B5_0B488ADB4269_.wvu.Cols: 'FE-63'!$E:$E
Name Z_2C0D9096_8D85_462A_A9B5_0B488ADB4269_.wvu.Cols: 'FE-64'!$E:$E
Name Z_2C0D9096_8D85_462A_A9B5_0B488ADB4269_.wvu.Cols: 'FE-65'!$E:$E
Name Z_2C0D9096_8D85_462A_A9B5_0B488ADB4269_.wvu.Cols: 'FE-66'!$E:$E
Name Z_2C0D9096_8D85_462A_A9B5_0B488ADB4269_.wvu.Cols: 'FE-71'!$E:$E
Name Z_2C0D9096_8D85_462A_A9B5_0B488ADB4269_.wvu.Cols: 'FE-72'!$E:$E
Name Z_2C0D9096_8D85_462A_A9B5_0B488ADB4269_.wvu.Cols: 'FE-73'!$E:$E
Name Z_2C0D9096_8D85_462A_A9B5_0B488ADB4269_.wvu.Cols: 'FE-74'!$E:$E
Name Z_2C0D9096_8D85_462A_A9B5_0B488ADB4269_.wvu.Cols: 'FE-75'!$E:$E
Name Z_2C0D9096_8D85_462A_A9B5_0B488ADB4269_.wvu.Cols: 'FE-76'!$E:$E
Name Z_2C0D9096_8D85_462A_A9B5_0B488ADB4269_.wvu.Cols: 'FE-77'!$E:$E
Name Z_2C0D9096_8D85_462A_A9B5_0B488ADB4269_.wvu.Cols: 'FE-78'!$E:$E
Name Z_2C0D9096_8D85_462A_A9B5_0B488ADB4269_.wvu.Cols: 'FE-79'!$E:$E
Name Z_2C0D9096_8D85_462A_A9B5_0B488ADB4269_.wvu.Cols: 'FE-82'!$E:$E
Name Z_2C0D9096_8D85_462A_A9B5_0B488ADB4269_.wvu.Cols: 'FE-83'!$E:$E
Name Z_2C0D9096_8D85_462A_A9B5_0B488ADB4269_.wvu.Cols: 'FE-84'!$E:$E
Name Z_2C0D9096_8D85_462A_A9B5_0B488ADB4269_.wvu.Cols: 'FE-85'!$E:$E
Name Z_2C0D9096_8D85_462A_A9B5_0B488ADB4269_.wvu.Cols: 'FE-86'!$E:$E
Name Z_2C0D9096_8D85_462A_A9B5_0B488ADB4269_.wvu.Cols: 'FE-87'!$E:$E
Name Z_2C0D9096_8D85_462A_A9B5_0B488ADB4269_.wvu.Cols: 'FE-88'!$E:$E
Name Z_2C0D9096_8D85_462A_A9B5_0B488ADB4269_.wvu.Cols: 'FE-90'!$E:$E
Name Z_2C0D9096_8D85_462A_A9B5_0B488ADB4269_.wvu.Cols: 'FE-97'!$E:$E
Name Z_2C0D9096_8D85_462A_A9B5_0B488ADB4269_.wvu.Cols: 'FE-98'!$E:$E
Name Z_2C0D9096_8D85_462A_A9B5_0B488ADB4269_.wvu.PrintArea: Statistics!$A:$I
Name Z_6F1DCD5D_5DAC_4817_BF40_2B66F6F593E6_.wvu.Cols: 'FE-01'!$E:$E
Name Z_6F1DCD5D_5DAC_4817_BF40_2B66F6F593E6_.wvu.Cols: 'FE-03'!$E:$E
Name Z_6F1DCD5D_5DAC_4817_BF40_2B66F6F593E6_.wvu.Cols: 'FE-05'!$E:$E
Name Z_6F1DCD5D_5DAC_4817_BF40_2B66F6F593E6_.wvu.Cols: 'FE-06'!$E:$E
Name Z_6F1DCD5D_5DAC_4817_BF40_2B66F6F593E6_.wvu.Cols: 'FE-07'!$E:$E
Name Z_6F1DCD5D_5DAC_4817_BF40_2B66F6F593E6_.wvu.Cols: 'FE-08'!$E:$E

Sheet Guideline
A1: Guideline to make and understand Unit Test Case
A3: 1. Overview
A4: - In the template, Unit test cases are based on functions. Each sheet presents test cases for one function.
A5: - Cover: General information of the project and Unit Test cases
A6: - FunctionList: The list of Classes and Functions in the document. + To control that the number of Unit TC meets customer's requirement or the norm, user should fill value for 'Normal number of Test cases/KLOC'.
A7: + Click on Function link to open the related Test cases of the function. Note: You should create new Function sheet before creating the link
A8: - Test Report: provive the overview results of Functions Unit test: Test coverage, Test successful coverage (Summary, for normal/abnormal/boundary cases)
A9: Note: Should check the formula of "Sub Total" if you add more functions
A11: 2. Content in Test function sheet
A12: 2.1 Combination of test cases.
A13: - To verify that number of Unit TC meets customer's requirement or not. User has to fill number LOC of tested function and fill value of 'Normal number test cases/KLOC' item in FunctionList sheet, which is required by customer or normal value. The number of lacked TC is shown in 'Lack of test cases' item.
A14: - If the number of Unit TC does not meet the requirement, creator should explain the reasons.
... A47: - Test requirement: Brief description about requirements which are tested in this function, it is not mandatory.

Sheet Cover
B2: UNIT TEST DOCUMENT
A4: Project Name | B4: Building a real-time platform to support exam management and organization at FPT University using Clean Architecture, NextJS, .Net, MySQL, and Zalo Mini App | E4: Creator | F4: TuanND, BaoPG, ThangTVB, AnhNN, Quang TVD
A5: Project Code | B5: FUEM | E5: Issue Date | F5: 45679
A6: Document Code | B6: FUEM_Report5_Test Report_v1.0 | E6: Version | F6: v1.03
A9: Record of change
A10: Effective Date | B10: Version | C10: Change Item | D10: *A,D,M | E10: Change description | F10: Reference
A11: 45679 | B11: v1.0 | C11: All Document | D11: A | E11: Create document
A12: 45713 | B12: v1.01 | C12: All Document | D12: M | E12: Modify sample template baseline for API Testing
A13: 45748 | B13: 1.02 | C13: All Document | D13: M | E13: Baseline document
A14: 45767 | B14: v1.03 | C14: All Document | D14: M | E14: Fix comment Mentor

Sheet Functions
E2: Function List
A4: Project Name | E4: =Cover!B4 -> Building a real-time platform to support exam management and organization at FPT University using Clean Architecture, NextJS, .Net, MySQL, and Zalo Mini App
A5: Project Code | E5: =Cover!B5 -> FUEM
A6: Normal number of Test cases/KLOC | E6: 20
A7: Test Environment Setup Description | E7: 1. Server - FE: https://dev.nextexam.tech - BE: https://api-dev.nextexam.tech - Zalo Mini App: FPT University Exam 2. Database: nextexam-dev 3. Web Browser: Chrome
A10: No | B10: Requirement Name | C10: Class Name | D10: Function Name | E10: Function Code(Optional) | F10: Sheet Name | G10: Description | H10: Pre-Condition
A11: 1 | B11: Sign in with Microsoft account & Google Account | C11: IdentityController | D11: FE-01_Sign in with Microsoft account & Google Account | E11: FE-01 | F11: FE-01
A12: 2 | B12: [ZMP] Log in with zalo account | C12: IdentityController | D12: FE-03_[ZMP] Log in with zalo account | E12: FE-03 | F12: FE-03
A13: 3 | B13: View the list of users on the system | C13: IdentityController | D13: FE-05_View the list of users on the system | E13: FE-05 | F13: FE-05
A14: 4 | B14: View and update user details | C14: IdentityController | D14: FE-06_View and update user details | E14: FE-06 | F14: FE-06
A15: 5 | B15: Add users with access to the system | C15: IdentityController | D15: FE-07_Add users with access to the system | E15: FE-07 | F15: FE-07
A16: 6 | B16: Lock user accounts | C16: IdentityController | D16: FE-08_Lock user accounts | E16: FE-08 | F16: FE-08
A17: 7 | B17: Import users using excel file | C17: IdentityController | D17: FE-09_Import users using excel file | E17: FE-09 | F17: FE-09
A18: 8 | B18: View list of departments | C18: DepartmentsController | D18: FE-10_View list of departments | E18: FE-10 | F18: FE-10
A19: 9 | B19: CRUD department | C19: DepartmentsController | D19: FE-11_CRUD department | E19: FE-11 | F19: FE-11
A20: 10 | B20: View list of classrooms | C20: RoomsController | D20: FE-12_View list of classrooms | E20: FE-12 | F20: FE-12
A21: 11 | B21: CRUD classroom | C21: RoomsController | D21: FE-13_CRUD classroom | E21: FE-13 | F21: FE-13
A22: 12 | B22: Import classroom via excel file | C22: RoomsController | D22: FE-14_Import classroom via excel file | E22: FE-14 | F22: FE-14
... A76: 66 | B76: Send notifications about the server being open to the exam rooms | C76: ExamsCodeController | D76: FE-69_Send notifications about the server being open to the exam rooms | E76: FE-69 | F76: FE-69
A77: 67 | B77: [ZMP] Get information about exam code and exam regulations for that subject | D77: FE-70_[ZMP] Get information about exam code and exam regulations for that subject | E77: FE-70 | F77: FE-70
A78: 68 | B78: View the list of exam supervisors by day | C78: RegistrationsController | D78: FE-71_View the list of exam supervisors by day | E78: FE-71 | F78: FE-71
A79: 69 | B79: Update the status of receiving and resending paper exam documents | C79: RegistrationsController | D79: FE-72_Update the status of receiving and resending paper exam documents | E79: FE-72 | F79: FE-72
A80: 70 | B80: Calculate exam supervisor exam time | C80: ExamRoomsController | D80: FE-73_Calculate exam supervisor exam time | E80: FE-73 | F80: FE-73
A81: 71 | B81: Export exam supervisor exam time statistics | C81: ExamRoomsController | D81: FE-74_Export exam supervisor exam time statistics | E81: FE-74 | F81: FE-74
A82: 72 | B82: [ZMP] Create a new issue for a candidate. | C82: TicketsController | D82: FE-75_[ZMP] Create a new issue for a candidate. | E82: FE-75 | F82: FE-75
A83: 73 | B83: [ZMP] Tracking the status and feedback of the issue. | C83: TicketsController | D83: FE-76_[ZMP] Tracking the status and feedback of the issue. | E83: FE-76 | F83: FE-76
A84: 74 | B84: [ZMP] Communicate with the handling staff about the issue. | C84: TicketsController | D84: FE-77_[ZMP] Communicate with the handling staff about the issue. | E84: FE-77 | F84: FE-77
A85: 75 | B85: View the list of issue categories. | C85: TicketCategoryController | D85: FE-78_View the list of issue categories. | E85: FE-78 | F85: FE-78
A86: 76 | B86: CRUD issue categories. | C86: TicketCategoryController | D86: FE-79_CRUD issue categories. | E86: FE-79 | F86: FE-79
A87: 77 | B87: View list of issues | C87: TicketsController | D87: FE-82_View list of issues | E87: FE-82 | F87: FE-82
A88: 78 | B88: View the list of issues assigned to me | C88: TicketsController | D88: FE-83_View the list of issues assigned to me | E88: FE-83 | F88: FE-83
A89: 79 | B89: View list of issues by category | C89: TicketsController | D89: FE-84_View list of issues by category | E89: FE-84 | F89: FE-84
... A103: 95 | B103: Export summary report file by day | C103: ExportController | D103: FE-100_Export summary report file by day | E103: FE-100 | F103: FE-100
A104: 96 | B104: Chat with AI about exam issues | D104: FE-101_Chat with AI about exam isssues | E104: FE-101 | F104: FE-101

Sheet Statistics
A2: UNIT TEST REPORT
A4: Project Name | B4: =Cover!B4 -> Building a real-time platform to support exam management and organization at FPT University using Clean Architecture, NextJS, .Net, MySQL, and Zalo Mini App | D4: Creator | F4: TuanND
A5: Project Code | B5: =Cover!B5 -> FUEM | D5: Reviewer/Approver | F5: BaoPG
A6: Document Code | B6: =B5&"_"&"Test Report"&"_"&"v1.0" -> FUEM_Test Report_v1.0 | D6: Issue Date | F6: 45768
A7: Notes
A11: No | B11: Function code | C11: Passed | D11: Failed | E11: Untested | F11: N | G11: A | H11: B | I11: Total Test Cases
A12: 1 | B12: FE-01 | C12: =INDIRECT("'" & B12 & "'!A7") -> 5 | D12: =INDIRECT("'" & B12 & "'!C7") -> 0 | E12: =INDIRECT("'" & B12 & "'!F7") -> 0 | F12: =INDIRECT("'" & B12 & "'!L7") -> 1 | G12: =INDIRECT("'" & B12 & "'!M7") -> 4 | H12: =INDIRECT("'" & B12 & "'!N7") -> 0 | I12: =INDIRECT("'" & B12 & "'!O7") -> 5
A13: 2 | B13: FE-03 | C13: =INDIRECT("'" & B13 & "'!A7") -> 5 | D13: =INDIRECT("'" & B13 & "'!C7") -> 0 | E13: =INDIRECT("'" & B13 & "'!F7") -> 0 | F13: =INDIRECT("'" & B13 & "'!L7") -> 1 | G13: =INDIRECT("'" & B13 & "'!M7") -> 4 | H13: =INDIRECT("'" & B13 & "'!N7") -> 0 | I13: =INDIRECT("'" & B13 & "'!O7") -> 5
A14: 3 | B14: FE-05 | C14: =INDIRECT("'" & B14 & "'!A7") -> 9 | D14: =INDIRECT("'" & B14 & "'!C7") -> 0 | E14: =INDIRECT("'" & B14 & "'!F7") -> 0 | F14: =INDIRECT("'" & B14 & "'!L7") -> 5 | G14: =INDIRECT("'" & B14 & "'!M7") -> 4 | H14: =INDIRECT("'" & B14 & "'!N7") -> 0 | I14: =INDIRECT("'" & B14 & "'!O7") -> 9
A15: 4 | B15: FE-06 | C15: =INDIRECT("'" & B15 & "'!A7") -> 7 | D15: =INDIRECT("'" & B15 & "'!C7") -> 0 | E15: =INDIRECT("'" & B15 & "'!F7") -> 0 | F15: =INDIRECT("'" & B15 & "'!L7") -> 7 | G15: =INDIRECT("'" & B15 & "'!M7") -> 0 | H15: =INDIRECT("'" & B15 & "'!N7") -> 0 | I15: =INDIRECT("'" & B15 & "'!O7") -> 7
A16: 5 | B16: FE-07 | C16: =INDIRECT("'" & B16 & "'!A7") -> 6 | D16: =INDIRECT("'" & B16 & "'!C7") -> 0 | E16: =INDIRECT("'" & B16 & "'!F7") -> 0 | F16: =INDIRECT("'" & B16 & "'!L7") -> 6 | G16: =INDIRECT("'" & B16 & "'!M7") -> 0 | H16: =INDIRECT("'" & B16 & "'!N7") -> 0 | I16: =INDIRECT("'" & B16 & "'!O7") -> 6
A17: 6 | B17: FE-08 | C17: =INDIRECT("'" & B17 & "'!A7") -> 5 | D17: =INDIRECT("'" & B17 & "'!C7") -> 0 | E17: =INDIRECT("'" & B17 & "'!F7") -> 0 | F17: =INDIRECT("'" & B17 & "'!L7") -> 5 | G17: =INDIRECT("'" & B17 & "'!M7") -> 0 | H17: =INDIRECT("'" & B17 & "'!N7") -> 0 | I17: =INDIRECT("'" & B17 & "'!O7") -> 5
A18: 7 | B18: FE-09 | C18: =INDIRECT("'" & B18 & "'!A7") -> 3 | D18: =INDIRECT("'" & B18 & "'!C7") -> 0 | E18: =INDIRECT("'" & B18 & "'!F7") -> 0 | F18: =INDIRECT("'" & B18 & "'!L7") -> 1 | G18: =INDIRECT("'" & B18 & "'!M7") -> 2 | H18: =INDIRECT("'" & B18 & "'!N7") -> 0 | I18: =INDIRECT("'" & B18 & "'!O7") -> 3
A19: 8 | B19: FE-10 | C19: =INDIRECT("'" & B19 & "'!A7") -> 6 | D19: =INDIRECT("'" & B19 & "'!C7") -> 0 | E19: =INDIRECT("'" & B19 & "'!F7") -> 0 | F19: =INDIRECT("'" & B19 & "'!L7") -> 3 | G19: =INDIRECT("'" & B19 & "'!M7") -> 3 | H19: =INDIRECT("'" & B19 & "'!N7") -> 0 | I19: =INDIRECT("'" & B19 & "'!O7") -> 6
A20: 9 | B20: FE-11 | C20: =INDIRECT("'" & B20 & "'!A7") -> 15 | D20: =INDIRECT("'" & B20 & "'!C7") -> 0 | E20: =INDIRECT("'" & B20 & "'!F7") -> 0 | F20: =INDIRECT("'" & B20 & "'!L7") -> 4 | G20: =INDIRECT("'" & B20 & "'!M7") -> 11 | H20: =INDIRECT("'" & B20 & "'!N7") -> 0 | I20: =INDIRECT("'" & B20 & "'!O7") -> 15
A21: 10 | B21: FE-12 | C21: =INDIRECT("'" & B21 & "'!A7") -> 9 | D21: =INDIRECT("'" & B21 & "'!C7") -> 0 | E21: =INDIRECT("'" & B21 & "'!F7") -> 0 | F21: =INDIRECT("'" & B21 & "'!L7") -> 6 | G21: =INDIRECT("'" & B21 & "'!M7") -> 3 | H21: =INDIRECT("'" & B21 & "'!N7") -> 0 | I21: =INDIRECT("'" & B21 & "'!O7") -> 9
A22: 11 | B22: FE-13 | C22: =INDIRECT("'" & B22 & "'!A7") -> 17 | D22: =INDIRECT("'" & B22 & "'!C7") -> 0 | E22: =INDIRECT("'" & B22 & "'!F7") -> 0 | F22: =INDIRECT("'" & B22 & "'!L7") -> 4 | G22: =INDIRECT("'" & B22 & "'!M7") -> 13 | H22: =INDIRECT("'" & B22 & "'!N7") -> 0 | I22: =INDIRECT("'" & B22 & "'!O7") -> 17
A23: 12 | B23: FE-14 | C23: =INDIRECT("'" & B23 & "'!A7") -> 3 | D23: =INDIRECT("'" & B23 & "'!C7") -> 0 | E23: =INDIRECT("'" & B23 & "'!F7") -> 0 | F23: =INDIRECT("'" & B23 & "'!L7") -> 1 | G23: =INDIRECT("'" & B23 & "'!M7") -> 2 | H23: =INDIRECT("'" & B23 & "'!N7") -> 0 | I23: =INDIRECT("'" & B23 & "'!O7") -> 3
A24: 13 | B24: FE-15 | C24: =INDIRECT("'" & B24 & "'!A7") -> 9 | D24: =INDIRECT("'" & B24 & "'!C7") -> 0 | E24: =INDIRECT("'" & B24 & "'!E7") -> 0 | F24: =INDIRECT("'" & B24 & "'!K7") -> 6 | G24: =INDIRECT("'" & B24 & "'!L7") -> 3 | H24: =INDIRECT("'" & B24 & "'!M7") -> 0 | I24: =INDIRECT("'" & B24 & "'!N7") -> 9
A25: 14 | B25: FE-16 | C25: =INDIRECT("'" & B25 & "'!A7") -> 17 | D25: =INDIRECT("'" & B25 & "'!C7") -> 0 | E25: =INDIRECT("'" & B25 & "'!E7") -> 0 | F25: =INDIRECT("'" & B25 & "'!K7") -> 4 | G25: =INDIRECT("'" & B25 & "'!L7") -> 13 | H25: =INDIRECT("'" & B25 & "'!M7") -> 0 | I25: =INDIRECT("'" & B25 & "'!N7") -> 17
A26: 15 | B26: FE-17 | C26: =INDIRECT("'" & B26 & "'!A7") -> 3 | D26: =INDIRECT("'" & B26 & "'!C7") -> 0 | E26: =INDIRECT("'" & B26 & "'!F7") -> 0 | F26: =INDIRECT("'" & B26 & "'!L7") -> 1 | G26: =INDIRECT("'" & B26 & "'!M7") -> 2 | H26: =INDIRECT("'" & B26 & "'!N7") -> 0 | I26: =INDIRECT("'" & B26 & "'!O7") -> 3
A27: 16 | B27: FE-18 | C27: =INDIRECT("'" & B27 & "'!A7") -> 9 | D27: =INDIRECT("'" & B27 & "'!C7") -> 0 | E27: =INDIRECT("'" & B27 & "'!E7") -> 0 | F27: =INDIRECT("'" & B27 & "'!K7") -> 6 | G27: =INDIRECT("'" & B27 & "'!L7") -> 3 | H27: =INDIRECT("'" & B27 & "'!M7") -> 0 | I27: =INDIRECT("'" & B27 & "'!N7") -> 9
A28: 17 | B28: FE-19 | C28: =INDIRECT("'" & B28 & "'!A7") -> 17 | D28: =INDIRECT("'" & B28 & "'!C7") -> 0 | E28: =INDIRECT("'" & B28 & "'!E7") -> 0 | F28: =INDIRECT("'" & B28 & "'!K7") -> 4 | G28: =INDIRECT("'" & B28 & "'!L7") -> 13 | H28: =INDIRECT("'" & B28 & "'!M7") -> 0 | I28: =INDIRECT("'" & B28 & "'!N7") -> 17
A29: 18 | B29: FE-20 | C29: =INDIRECT("'" & B29 & "'!A7") -> 3 | D29: =INDIRECT("'" & B29 & "'!C7") -> 0 | E29: =INDIRECT("'" & B29 & "'!F7") -> 0 | F29: =INDIRECT("'" & B29 & "'!L7") -> 1 | G29: =INDIRECT("'" & B29 & "'!M7") -> 2 | H29: =INDIRECT("'" & B29 & "'!N7") -> 0 | I29: =INDIRECT("'" & B29 & "'!O7") -> 3
A30: 19 | B30: FE-21 | C30: =INDIRECT("'" & B30 & "'!A7") -> 9 | D30: =INDIRECT("'" & B30 & "'!C7") -> 0 | E30: =INDIRECT("'" & B30 & "'!E7") -> 0 | F30: =INDIRECT("'" & B30 & "'!K7") -> 6 | G30: =INDIRECT("'" & B30 & "'!L7") -> 3 | H30: =INDIRECT("'" & B30 & "'!M7") -> 0 | I30: =INDIRECT("'" & B30 & "'!N7") -> 9
A31: 20 | B31: FE-22 | C31: =INDIRECT("'" & B31 & "'!A7") -> 17 | D31: =INDIRECT("'" & B31 & "'!C7") -> 0 | E31: =INDIRECT("'" & B31 & "'!E7") -> 0 | F31: =INDIRECT("'" & B31 & "'!K7") -> 4 | G31: =INDIRECT("'" & B31 & "'!L7") -> 13 | H31: =INDIRECT("'" & B31 & "'!M7") -> 0 | I31: =INDIRECT("'" & B31 & "'!N7") -> 17
A32: 21 | B32: FE-23 | C32: =INDIRECT("'" & B32 & "'!A7") -> 9 | D32: =INDIRECT("'" & B32 & "'!C7") -> 0 | E32: =INDIRECT("'" & B32 & "'!E7") -> 0 | F32: =INDIRECT("'" & B32 & "'!K7") -> 6 | G32: =INDIRECT("'" & B32 & "'!L7") -> 3 | H32: =INDIRECT("'" & B32 & "'!M7") -> 0 | I32: =INDIRECT("'" & B32 & "'!N7") -> 9
A33: 22 | B33: FE-24 | C33: =INDIRECT("'" & B33 & "'!A7") -> 17 | D33: =INDIRECT("'" & B33 & "'!C7") -> 0 | E33: =INDIRECT("'" & B33 & "'!E7") -> 0 | F33: =INDIRECT("'" & B33 & "'!K7") -> 4 | G33: =INDIRECT("'" & B33 & "'!L7") -> 13 | H33: =INDIRECT("'" & B33 & "'!M7") -> 0 | I33: =INDIRECT("'" & B33 & "'!N7") -> 17
A34: 23 | B34: FE-26 | C34: =INDIRECT("'" & B34 & "'!A7") -> 9 | D34: =INDIRECT("'" & B34 & "'!C7") -> 0 | E34: =INDIRECT("'" & B34 & "'!F7") -> 0 | F34: =INDIRECT("'" & B34 & "'!L7") -> 6 | G34: =INDIRECT("'" & B34 & "'!M7") -> 3 | H34: =INDIRECT("'" & B34 & "'!N7") -> 0 | I34: =INDIRECT("'" & B34 & "'!O7") -> 9
A35: 24 | B35: FE-27 | C35: =INDIRECT("'" & B35 & "'!A7") -> 19 | D35: =INDIRECT("'" & B35 & "'!C7") -> 0 | E35: =INDIRECT("'" & B35 & "'!F7") -> 0 | F35: =INDIRECT("'" & B35 & "'!L7") -> 4 | G35: =INDIRECT("'" & B35 & "'!M7") -> 15 | H35: =INDIRECT("'" & B35 & "'!N7") -> 0 | I35: =INDIRECT("'" & B35 & "'!O7") -> 19
A36: 25 | B36: FE-28 | C36: =INDIRECT("'" & B36 & "'!A7") -> 4 | D36: =INDIRECT("'" & B36 & "'!C7") -> 0 | E36: =INDIRECT("'" & B36 & "'!E7") -> 0 | F36: =INDIRECT("'" & B36 & "'!K7") -> 1 | G36: =INDIRECT("'" & B36 & "'!L7") -> 3 | H36: =INDIRECT("'" & B36 & "'!M7") -> 0 | I36: =INDIRECT("'" & B36 & "'!N7") -> 4
A37: 26 | B37: FE-29 | C37: =INDIRECT("'" & B37 & "'!A7") -> 9 | D37: =INDIRECT("'" & B37 & "'!C7") -> 0 | E37: =INDIRECT("'" & B37 & "'!E7") -> 0 | F37: =INDIRECT("'" & B37 & "'!K7") -> 6 | G37: =INDIRECT("'" & B37 & "'!L7") -> 3 | H37: =INDIRECT("'" & B37 & "'!M7") -> 0 | I37: =INDIRECT("'" & B37 & "'!N7") -> 9
A38: 27 | B38: FE-30 | C38: =INDIRECT("'" & B38 & "'!A7") -> 17 | D38: =INDIRECT("'" & B38 & "'!C7") -> 0 | E38: =INDIRECT("'" & B38 & "'!E7") -> 0 | F38: =INDIRECT("'" & B38 & "'!K7") -> 4 | G38: =INDIRECT("'" & B38 & "'!L7") -> 13 | H38: =INDIRECT("'" & B38 & "'!M7") -> 0 | I38: =INDIRECT("'" & B38 & "'!N7") -> 17
A39: 28 | B39: FE-31 | C39: =INDIRECT("'" & B39 & "'!A7") -> 9 | D39: =INDIRECT("'" & B39 & "'!C7") -> 0 | E39: =INDIRECT("'" & B39 & "'!E7") -> 0 | F39: =INDIRECT("'" & B39 & "'!K7") -> 6 | G39: =INDIRECT("'" & B39 & "'!L7") -> 3 | H39: =INDIRECT("'" & B39 & "'!M7") -> 0 | I39: =INDIRECT("'" & B39 & "'!N7") -> 9
A40: 29 | B40: FE-32 | C40: =INDIRECT("'" & B40 & "'!A7") -> 5 | D40: =INDIRECT("'" & B40 & "'!C7") -> 0 | E40: =INDIRECT("'" & B40 & "'!E7") -> 0 | F40: =INDIRECT("'" & B40 & "'!K7") -> 1 | G40: =INDIRECT("'" & B40 & "'!L7") -> 4 | H40: =INDIRECT("'" & B40 & "'!M7") -> 0 | I40: =INDIRECT("'" & B40 & "'!N7") -> 5
A41: 30 | B41: FE-33 | C41: =INDIRECT("'" & B41 & "'!A7") -> 3 | D41: =INDIRECT("'" & B41 & "'!C7") -> 0 | E41: =INDIRECT("'" & B41 & "'!E7") -> 0 | F41: =INDIRECT("'" & B41 & "'!K7") -> 1 | G41: =INDIRECT("'" & B41 & "'!L7") -> 2 | H41: =INDIRECT("'" & B41 & "'!M7") -> 0 | I41: =INDIRECT("'" & B41 & "'!N7") -> 3
A42: 31 | B42: FE-34 | C42: =INDIRECT("'" & B42 & "'!A7") -> 6 | D42: =INDIRECT("'" & B42 & "'!C7") -> 0 | E42: =INDIRECT("'" & B42 & "'!F7") -> 0 | F42: =INDIRECT("'" & B42 & "'!L7") -> 3 | G42: =INDIRECT("'" & B42 & "'!M7") -> 3 | H42: =INDIRECT("'" & B42 & "'!N7") -> 0 | I42: =INDIRECT("'" & B42 & "'!O7") -> 6
A43: 32 | B43: FE-35 | C43: =INDIRECT("'" & B43 & "'!A7") -> 17 | D43: =INDIRECT("'" & B43 & "'!C7") -> 0 | E43: =INDIRECT("'" & B43 & "'!F7") -> 0 | F43: =INDIRECT("'" & B43 & "'!L7") -> 4 | G43: =INDIRECT("'" & B43 & "'!M7") -> 13 | H43: =INDIRECT("'" & B43 & "'!N7") -> 0 | I43: =INDIRECT("'" & B43 & "'!O7") -> 17
A44: 33 | B44: FE-36 | C44: =INDIRECT("'" & B44 & "'!A7") -> 4 | D44: =INDIRECT("'" & B44 & "'!C7") -> 0 | E44: =INDIRECT("'" & B44 & "'!F7") -> 0 | F44: =INDIRECT("'" & B44 & "'!L7") -> 1 | G44: =INDIRECT("'" & B44 & "'!M7") -> 3 | H44: =INDIRECT("'" & B44 & "'!N7") -> 0 | I44: =INDIRECT("'" & B44 & "'!O7") -> 4
A45: 34 | B45: FE-37 | C45: =INDIRECT("'" & B45 & "'!A7") -> 6 | D45: =INDIRECT("'" & B45 & "'!C7") -> 0 | E45: =INDIRECT("'" & B45 & "'!F7") -> 0 | F45: =INDIRECT("'" & B45 & "'!L7") -> 3 | G45: =INDIRECT("'" & B45 & "'!M7") -> 3 | H45: =INDIRECT("'" & B45 & "'!N7") -> 0 | I45: =INDIRECT("'" & B45 & "'!O7") -> 6
...

Sheet FE-01
A2: Function Code | C2: FE-01 | F2: Function Name | L2: FE-01_Sign in with Microsoft account & Google Account
A3: Created By | C3: BaoPG | F3: Executed By | L3: BaoPG
A4: Lines of code | C4: 250 | F4: Lack of test cases | L4: =IF(Functions!E6<>"N/A",SUM(C4*Functions!E6/1000,-O7),"N/A") -> 0
A5: Test requirement | C5: N/A
A6: Passed | C6: Failed | F6: Untested | L6: N/A/B | O6: Total Test Cases
A7: =COUNTIF(F47:HQ47,"P") -> 5 | C7: =COUNTIF(F47:HQ47,"F") -> 0 | F7: =SUM(O7,-A7,-C7) -> 0 | L7: =COUNTIF(E46:HQ46,"N") -> 1 | M7: =COUNTIF(E46:HQ46,"A") -> 4 | N7: =COUNTIF(E46:HQ46,"B") -> 0 | O7: =COUNTA(E9:HT9) -> 5
F9: UTCID01 | G9: UTCID02 | H9: UTCID03 | I9: UTCID04 | J9: UTCID05
A10: Condition | B10: Precondition
D12: Account have permission in the database | F12: O | J12: O
D13: Account don't have permission in the database | I13: O
B14: HTTP Method
D15: POST | F15: O | G15: O | H15: O | I15: O | J15: O
B16: API Endpoint
B17: api/user/login-with-account | F17: O | G17: O | H17: O | I17: O | J17: O
B19: Input
B20: Token
B21: Valid Token | F21: O | I21: O | J21: O
B22: Invalid Token | H22: O
D23: abcd | G23: O
A28: Confirm | B28: Return
D29: 200: Success | F29: O
D30: 400: Bad Request | G30: O
D31: 401: Unauthorized | H31: O
D32: 403: No Permission | I32: O
D33: 500: Internal Server Error | J33: O
B37: Exception
B39: Log message
B40: "User logged in successfully with a valid token" | F40: O
B41: "Failed to log in: Missing or invalid token format" | G41: O
B42: "Failed to log in: Invalid token" | H42: O
B43: "Failed to log in: Account does not have permission" | I43: O
B44: "Unexpected error occurred" | J44: O
A46: Result | B46: Type(N : Normal, A : Abnormal, B : Boundary) | F46: N | G46: A | H46: A | I46: A | J46: A
B47: Passed/Failed | F47: P | G47: P | H47: P | I47: P | J47: P
B48: Executed Date | F48: 45721 | G48: 45721 | H48: 45721 | I48: 45721 | J48: 45721
B49: Defect ID

Sheet FE-03
A2: Function Code | C2: FE-03 | F2: Function Name | L2: FE-03_[ZMP] Log in with zalo account
A3: Created By | C3: BaoPG | F3: Executed By | L3: BaoPG
A4: Lines of code | C4: 100 | F4: Lack of test cases | L4: =IF(Functions!E6<>"N/A",SUM(C4*Functions!E6/1000,-O7),"N/A") -> -3
A5: Test requirement | C5: N/A
A6: Passed | C6: Failed | F6: Untested | L6: N/A/B | O6: Total Test Cases
A7: =COUNTIF(F47:HQ47,"P") -> 5 | C7: =COUNTIF(F47:HQ47,"F") -> 0 | F7: =SUM(O7,-A7,-C7) -> 0 | L7: =COUNTIF(E46:HQ46,"N") -> 1 | M7: =COUNTIF(E46:HQ46,"A") -> 4 | N7: =COUNTIF(E46:HQ46,"B") -> 0 | O7: =COUNTA(E9:HT9) -> 5
F9: UTCID01 | G9: UTCID02 | H9: UTCID03 | I9: UTCID04 | J9: UTCID05
A10: Condition | B10: Precondition
D12: Account have permission in the database | F12: O | J12: O
D13: Account don't have permission in the database | I13: O
B14: HTTP Method
D15: POST | F15: O | G15: O | H15: O | I15: O | J15: O
B16: API Endpoint
B17: api/user/login-with-zalo | F17: O | G17: O | H17: O | I17: O | J17: O
B19: Input
B20: Token
B21: Valid Token | F21: O | I21: O | J21: O
B22: Invalid Token | H22: O
D23: abcd | G23: O
A28: Confirm | B28: Return
D29: 200: Success | F29: O
D30: 400: Bad Request | G30: O
D31: 401: Unauthorized | H31: O
D32: 403: No Permission | I32: O
D33: 500: Internal Server Error | J33: O
B37: Exception
B39: Log message
B40: "User logged in successfully with a valid token" | F40: O
B41: "Failed to log in: Missing or invalid token format" | G41: O
B42: "Failed to log in: Invalid token" | H42: O
B43: "Failed to log in: Account does not have permission" | I43: O
B44: "Unexpected error occurred" | J44: O
A46: Result | B46: Type(N : Normal, A : Abnormal, B : Boundary) | F46: N | G46: A | H46: A | I46: A | J46: A
B47: Passed/Failed | F47: P | G47: P | H47: P | I47: P | J47: P
B48: Executed Date | F48: 45721 | G48: 45721 | H48: 45721 | I48: 45721 | J48: 45721
B49: Defect ID

Sheet FE-05
A2: Function Code | C2: FE-05 | F2: Function Name | L2: FE-05_View the list of users on the system
A3: Created By | C3: AnhNN | F3: Executed By | L3: AnhNN
A4: Lines of code | C4: 100 | F4: Lack of test cases | L4: =IF(Functions!E6<>"N/A",SUM(C4*Functions!E6/1000,-O7),"N/A") -> -7
A5: Test requirement | C5: N/A
A6: Passed | C6: Failed | F6: Untested | L6: N/A/B | O6: Total Test Cases
A7: =COUNTIF(F48:HQ48,"P") -> 9 | C7: =COUNTIF(F48:HQ48,"F") -> 0 | F7: =SUM(O7,-A7,-C7) -> 0 | L7: =COUNTIF(E47:HQ47,"N") -> 5 | M7: =COUNTIF(E47:HQ47,"A") -> 4 | N7: =COUNTIF(E47:HQ47,"B") -> 0 | O7: =COUNTA(E9:HT9) -> 9
F9: UTCID01 | G9: UTCID02 | H9: UTCID03 | I9: UTCID04 | J9: UTCID05 | K9: UTCID06 | L9: UTCID07 | M9: UTCID08 | N9: UTCID09
A10: Condition | B10: Precondition
D11: Authorized | F11: O | G11: O | H11: O | I11: O | J11: O | K11: O | L11: O | N11: O
D12: At least 1 users records in the database | F12: O | G12: O | H12: O | I12: O | J12: O | K12: O | L12: O | M12: O
B14: HTTP Method
D15: GET | F15: O | G15: O | H15: O | I15: O | J15: O | K15: O | L15: O | M15: O | N15: O
B16: API Endpoint
B17: api/user | F17: O | M17: O
B18: api/user?PageNumber=0&PageSize=2 | G18: O | N18: O
B19: /api/user?name=phan gia bao | H19: O
B20: /api/user?PageNumber=0&PageSize=10&SortBy=FullName&SortOrder=1 | I20: O
B21: /api/user?PageNumber=-1 | G21: O | J21: O
B22: /api/user?PageSize=abc | K22: O
A28: Confirm | B28: Return
D29: 200: Success with 10 records | F29: O
D30: 200: Success with 20 records | G30: O
D31: 200: Success with records have name = "Phan Gia Bao" | H31: O
D32: 200: Success with 10 records is sorted | I32: O
D33: 200: Success with records have word "201" | J33: O
D34: 400: Bad Request | K34: O
D35: 403: No Permision | M35: O
D36: 404 : Not Found | N36: O
B38: Exception
B40: Log message
B41: "Get List of users successfully" | F41: O | G41: O | H41: O | I41: O | J41: O | K41: O
B42: "List of user not found" | N42: O
B43: "Invalid request parameters for getting list of user" | L43: O
B44: "User does not have permission to access the list of user" | M44: O
A47: Result | B47: Type(N : Normal, A : Abnormal, B : Boundary) | F47: N | G47: N | H47: N | I47: N | J47: N | K47: A | L47: A | M47: A | N47: A
B48: Passed/Failed | F48: P | G48: P | H48: P | I48: P | J48: P | K48: P | L48: P | M48: P | N48: P
B49: Executed Date | F49: 45780 | G49: 45780 | H49: 45780 | I49: 45780 | J49: 45780 | K49: 45780 | L49: 45780 | M49: 45780 | N49: 45780
B50: Defect ID

Sheet FE-06
A2: Function Code | C2: FE-06 | F2: Function Name | L2: FE-06_View and update user details
A3: Created By | C3: AnhNN | F3: Executed By | L3: AnhNN
A4: Lines of code | C4: 300 | F4: Lack of test cases | L4: =IF(Functions!E6<>"N/A",SUM(C4*Functions!E6/1000,-O7),"N/A") -> -1
A5: Test requirement | C5: N/A
A6: Passed | C6: Failed | F6: Untested | L6: N/A/B | O6: Total Test Cases
A7: =COUNTIF(F41:HQ41,"P") -> 7 | C7: =COUNTIF(F41:HQ41,"F") -> 0 | F7: =SUM(O7,-A7,-C7) -> 0 | L7: =COUNTIF(E40:HQ40,"N") -> 7 | M7: =COUNTIF(E40:HQ40,"A") -> 0 | N7: =COUNTIF(E40:HQ40,"B") -> 0 | O7: =COUNTA(E9:HT9) -> 7
F9: UTCID01 | G9: UTCID02 | H9: UTCID03 | I9: UTCID04 | J9: UTCID05 | K9: UTCID06 | L9: UTCID07
A10: Condition | B10: Precondition
D11: Authorized | F11: O | G11: O | H11: O | I11: O | K11: O | L11: O
B12: HTTP Method
D13: GET | F13: O | G13: O | H13: O | I13: O | J13: O | K13: O | L13: O
D14: PUT | F14: O | H14: O | I14: O | J14: O | K14: O
B15: API Endpoint
D16: api/user/{id} | F16: O | G16: O | H16: O | J16: O | K16: O
D17: api/user/999 | I17: O
D18: apii/user/{guid} | L18: O
B19: Input
D20: { "fullName": "Trần Phan Lan Anh", "email": "anhtpl@fe.edu.vn", "phoneNumber": "0964106456", "gender": "1", "departmentId": "4e56461e-8cea-4185-a83f-a8565380fbda", "role": "ADMIN" } | F20: O | I20: O | J20: O
D22: Role = 1 (Invalid parmenter) | K22: O | L22: O
D23: phone="0964106456" (existing) | G23: O
D24: email="anhtpl@fe.edu.vn" (existing) | H24: O
A26: Confirm | B26: Return
D27: 200 OK with updated user data | F27: O
D28: 404 Not Found | I28: O
D29: 400 Bad request | G29: O | H29: O | K29: O | L29: O
D30: 401 Unauthorized | J30: O
B31: Exception
B33: Log message
D34: Updated User successfully | F34: O
D35: Phone number already exists | G35: O
D36: Email already exists | H36: O
D37: "User dose not permission" | J37: O
D38: Not foun userId {userId} | L38: O
A40: Result | B40: Type(N : Normal, A : Abnormal, B : Boundary) | F40: N | G40: N | H40: N | I40: N | J40: N | K40: N | L40: N
B41: Passed/Failed | F41: P | G41: P | H41: P | I41: P | J41: P | K41: P | L41: P
B42: Executed Date | F42: 45780 | G42: 45780 | H42: 45780 | I42: 45780 | J42: 45780 | K42: 45780 | L42: 45780
B43: Defect ID

Sheet FE-07
A2: Function Code | C2: FE-07 | F2: Function Name | L2: FE-07_Add users with access to the system
A3: Created By | C3: AnhNN | F3: Executed By | L3: AnhNN
A4: Lines of code | C4: 300 | F4: Lack of test cases | L4: =IF(Functions!E6<>"N/A",SUM(C4*Functions!E6/1000,-O7),"N/A") -> 0
A5: Test requirement | C5: N/A
A6: Passed | C6: Failed | F6: Untested | L6: N/A/B | O6: Total Test Cases
A7: =COUNTIF(F50:HQ50,"P") -> 6 | C7: =COUNTIF(F50:HQ50,"F") -> 0 | F7: =SUM(O7,-A7,-C7) -> 0 | L7: =COUNTIF(E49:HQ49,"N") -> 6 | M7: =COUNTIF(E49:HQ49,"A") -> 0 | N7: =COUNTIF(E49:HQ49,"B") -> 0 | O7: =COUNTA(E9:HT9) -> 6
F9: UTCID01 | G9: UTCID02 | H9: UTCID03 | I9: UTCID04 | J9: UTCID05 | K9: UTCID06
A10: Condition | B10: Precondition
D11: Authorized | F11: O | G11: O | H11: O | I11: O | K11: O
B13: HTTP Method
D14: POST | F14: O | G14: O | H14: O | I14: O | J14: O | K14: O
B15: API Endpoint
D16: api/user | F16: O | G16: O | H16: O | I16: O | J16: O
D17: api/user/123 | K17: O
B18: Input
D21: { "fullName": "Nguyễn thị Hạnh", "email": "nhatanhkt0964106456@gmail.com", "departmentId": "4e56461e-8cea-4185-a83f-a8565380fbda", "role": "ADMIN", "phoneNumber": "0977693150", "gender": 1 } | F21: O | J21: O | K21: O
D23: { "fullName": "Nguyễn thị Hạnh", "email": "nguyennhatanh.dev6@gmail.com", "departmentId": "4e56461e-8cea-4185-a83f-a8565380fbda", "role": "ADMIN", "phoneNumber": "0977693150", "gender": 1 } | G23: O
D25: { "fullName": "Nguyễn thị Hạnh", "email": "nguyennhatanh.dev6@gmail.com", "departmentId": "4e56461e-8cea-4185-a83f-a8565380fbda", "role": "ADMIN", "phoneNumber": "0977693150", "gender": "Nữ } | H25: O
D27: { "fullName": "Nguyễn thị Hạnh", "email": "nhatanhkt0964106456@gmail.com", "departmentId": "4e56461e-8cea-4185-a83f-a8565380fbda", "role": "ADMIN", "phoneNumber": "0977693150", "gender": 1 } | I27: O
A32: Confirm | B32: Return
D33: 200 Created with user details | F33: O
D34: 400 Bad Request with error | H34: O
D35: 404 Not Found | K35: O
D36: 401 Unauthorized | J36: O
D37: 500 Internal Server error | G37: O | I37: O
D38: Username 'nhatanhkt0964106456' is already taken
D39: Phonenumber '0964106456' is already taken | G39: O
D40: Email 'nhatanhkt0964106456@gmail.com' is already taken
B41: Exception
B43: Log message
D44: "Create User succesfully" | F44: O
D45: "Username{userName} is already taken | I45: O
D46: Phonenumber {phoneNumber} is already taken | G46: O | I46: O
D47: Email {email} is already taken | I47: O
D48: "User does not permission" | J48: O
A49: Result | B49: Type(N : Normal, A : Abnormal, B : Boundary) | F49: N | G49: N | H49: N | I49: N | J49: N | K49: N
B50: Passed/Failed | F50: P | G50: P | H50: P | I50: P | J50: P | K50: P
B51: Executed Date | F51: 45765 | G51: 45765 | H51: 39140 | I51: 39141 | J51: 39142 | K51: 39143
B52: Defect ID

Sheet FE-08
A2: Function Code | C2: FE-08 | F2: Function Name | L2: FE-08_Lock user accounts
A3: Created By | C3: AnhNN | F3: Executed By | L3: AnhNN
A4: Lines of code | C4: 300 | F4: Lack of test cases | L4: =IF(Functions!E6<>"N/A",SUM(C4*Functions!E6/1000,-O7),"N/A") -> 1
A5: Test requirement | C5: N/A
A6: Passed | C6: Failed | F6: Untested | L6: N/A/B | O6: Total Test Cases
A7: =COUNTIF(F36:HQ36,"P") -> 5 | C7: =COUNTIF(F36:HQ36,"F") -> 0 | F7: =SUM(O7,-A7,-C7) -> 0 | L7: =COUNTIF(E35:HQ35,"N") -> 5 | M7: =COUNTIF(E35:HQ35,"A") -> 0 | N7: =COUNTIF(E35:HQ35,"B") -> 0 | O7: =COUNTA(E9:HT9) -> 5
F9: UTCID01 | G9: UTCID02 | H9: UTCID03 | I9: UTCID04 | J9: UTCID05
A10: Condition | B10: Precondition
D11: Authorized | F11: O | G11: O | I11: O | J11: O
D12: { "id": "08dd5a69-4ab7-458d-86f0-feb3abda9608" } | F12: O | G12: O | H12: O | I12: O
D13: { "id": "123456" } | J13: O
B14: HTTP Method
D15: POST | F15: O | G15: O | H15: O | I15: O | J15: O
B16: API Endpoint
D17: /api/user/lock | F17: O | H17: O | I17: O | J17: O
D18: /api/user/lock/999 | G18: O
A22: Confirm | B22: Return
D23: 200 OK | F23: O
D24: 404 Not Found | G24: O
D25: 401 Unauthorized | H25: O
D26: 500 Internal server error | I26: O
D27: 400 Bad request | J27: O
B28: Exception
D29: Not found user | I29: O
B30: Log message
D31: "Lock user Id {id}sucess" | F31: O
D32: "Lock user Id {id} failed"
D33: ""Not found user Id 08dd5a69-4ab7-458d-86f0-feb3abda9608 | I33: O
D34: "Invalid authorization" | H34: O
A35: Result | B35: Type(N : Normal, A : Abnormal, B : Boundary) | F35: N | G35: N | H35: N | I35: N | J35: N
B36: Passed/Failed | F36: P | G36: P | H36: P | I36: P | J36: P
B37: Executed Date | F37: 45780 | G37: 45780 | H37: 45780 | I37: 45780 | J37: 45780
B38: Defect ID

Sheet FE-09
A2: Function Code | C2: FE-09 | F2: Function Name | L2: FE-09_Import users using excel file
A3: Created By | C3: QuangTVD | F3: Executed By | L3: QuangTVD
A4: Lines of code | C4: 100 | F4: Lack of test cases | L4: =IF(Functions!E6<>"N/A",SUM(C4*Functions!E6/1000,-O7),"N/A") -> -1
A5: Test requirement | C5: N/A
A6: Passed | C6: Failed | F6: Untested | L6: N/A/B | O6: Total Test Cases
A7: =COUNTIF(F31:HQ31,"P") -> 3 | C7: =COUNTIF(F31:HQ31,"F") -> 0 | F7: =SUM(O7,-A7,-C7) -> 0 | L7: =COUNTIF(E30:HQ30,"N") -> 1 | M7: =COUNTIF(E30:HQ30,"A") -> 2 | N7: =COUNTIF(E30:HQ30,"B") -> 0 | O7: =COUNTA(E9:HT9) -> 3
F9: UTCID01 | G9: UTCID02 | H9: UTCID03
A10: Condition | B10: Precondition
D11: Authorized | F11: O | G11: O
B13: HTTP Method
D14: POST | F14: O | G14: O | H14: O
B15: API Endpoint
D16: /api/user/import | F16: O | G16: O | H16: O
B17: Input
B18: file
D19: Imported file follows the template | F19: O | H19: O
D20: Imported file does not follow the template | G20: O
A22: Confirm | B22: Return
D23: 200 Success | F23: O
D24: 400 Bad request | G24: O
D25: 401 Unauthorized | H25: O
B26: Log message
D27: Import successfully | F27: O
D28: Import failed: Invalid import file | G28: O
D29: Invalid authorization | H29: O
A30: Result | B30: Type(N : Normal, A : Abnormal, B : Boundary) | F30: N | G30: A | H30: A
B31: Passed/Failed | F31: P | G31: P | H31: P
B32: Executed Date | F32: 45757 | G32: 45757 | H32: 45757
B33: Defect ID

Sheet FE-10
A2: Function Code | C2: FE-10 | F2: Function Name | L2: FE-10_View list of departments
A3: Created By | C3: QuangTVD | F3: Executed By | L3: QuangTVD
A4: Lines of code | C4: 100 | F4: Lack of test cases | L4: =IF(Functions!E6<>"N/A",SUM(C4*Functions!E6/1000,-O7),"N/A") -> -4
A5: Test requirement | C5: N/A
A6: Passed | C6: Failed | F6: Untested | L6: N/A/B | O6: Total Test Cases
A7: =COUNTIF(F37:HQ37,"P") -> 6 | C7: =COUNTIF(F37:HQ37,"F") -> 0 | F7: =SUM(O7,-A7,-C7) -> 0 | L7: =COUNTIF(E36:HQ36,"N") -> 3 | M7: =COUNTIF(E36:HQ36,"A") -> 3 | N7: =COUNTIF(E36:HQ36,"B") -> 0 | O7: =COUNTA(E9:HT9) -> 6
F9: UTCID01 | G9: UTCID02 | H9: UTCID03 | I9: UTCID04 | J9: UTCID05 | K9: UTCID06
A10: Condition | B10: Precondition
D11: Authorized | F11: O | G11: O | H11: O | I11: O | J11: O
B12: UserRole=EXAMINER | F12: O | G12: O | H12: O | I12: O | J12: O
B13: HTTP Method
D14: GET | F14: O | G14: O | H14: O | I14: O | J14: O | K14: O
B15: API Endpoint
B16: api/departments | F16: O | K16: O
B17: api/departments?PageNumber=0&PageSize=20 | G17: O
B18: /api/departments?PageNumber=0&PageSize=10&SortBy=FullName&SortOrder=1 | H18: O
B19: /api/departments?PageNumber=-1 | I19: O | J19: O
B20: /api/departments?PageSize=abc
A22: Confirm | B22: Return
D23: 200: Success with 10 records | F23: O
D24: 200: Success with 20 records | G24: O
D25: 200: Success with 10 records is sorted | H25: O
D26: 400: Bad Request | I26: O | J26: O
D27: 401: Unauthorized | K27: O
D28: 404 : Not Found
B29: Log message
D30: Successfully get 10 records | F30: O | H30: O
D31: Successfully get 20 records | G31: O
D33: Invalid page number | I33: O
D34: Invalid page size | J34: O
D35: Unauthorized | K35: O
A36: Result | B36: Type(N : Normal, A : Abnormal, B : Boundary) | F36: N | G36: N | H36: N | I36: A | J36: A | K36: A
B37: Passed/Failed | F37: P | G37: P | H37: P | I37: P | J37: P | K37: P
B38: Executed Date | F38: 45757 | G38: 45757 | H38: 45757 | I38: 45757 | J38: 45757 | K38: 45757
B39: Defect ID

Sheet FE-11
A2: Function Code | C2: FE-11 | F2: Function Name | L2: FE-11_CRUD department
A3: Created By | C3: QuangTVD | F3: Executed By | L3: QuangTVD
A4: Lines of code | C4: 100 | F4: Lack of test cases | L4: =IF(Functions!E6<>"N/A",SUM(C4*Functions!E6/1000,-O7),"N/A") -> -13
A5: Test requirement | C5: N/A
A6: Passed | C6: Failed | F6: Untested | L6: N/A/B | O6: Total Test Cases
A7: =COUNTIF(F70:HQ70,"P") -> 15 | C7: =COUNTIF(F70:HQ70,"F") -> 0 | F7: =SUM(O7,-A7,-C7) -> 0 | L7: =COUNTIF(E69:HQ69,"N") -> 4 | M7: =COUNTIF(E69:HQ69,"A") -> 11 | N7: =COUNTIF(E69:HQ69,"B") -> 0 | O7: =COUNTA(E9:HT9) -> 15
F9: UTCID01 | G9: UTCID02 | H9: UTCID03 | I9: UTCID04 | J9: UTCID05 | K9: UTCID06 | L9: UTCID07 | M9: UTCID08 | N9: UTCID09 | O9: UTCID10 | P9: UTCID11 | Q9: UTCID12 | R9: UTCID13 | S9: UTCID14 | T9: UTCID15
A10: Condition | B10: Precondition
D11: Authorized | F11: O | G11: O | I11: O | J11: O | L11: O | M11: O | N11: O | P11: O | Q11: O | R11: O | T11: O
B12: User(id=1, fullName="Phan Gia Bao", email="BaoPG@nextexam.tech", phoneNumber="0905640120", gender="1", departmentId="16d3f8b4-e9ef-4a3e-af05-46f649761775", role="EXAMINER") | F12: O | G12: O | I12: O | J12: O | L12: O | M12: O | N12: O | P12: O | Q12: O | R12: O | T12: O
B13: Department with code "DEP_STUDENT_SERVICE" already existed | F13: O | G13: O | H13: O | I13: O | J13: O | K13: O | L13: O | M13: O | N13: O | O13: O | P13: O | Q13: O
B14: HTTP Method
D15: GET | F15: O | G15: O | H15: O
D16: POST | I16: O | J16: O | K16: O | L16: O
D17: PATCH | M17: O | N17: O | O17: O | P17: O | Q17: O
D18: DELETE | R18: O | S18: O | T18: O
B19: API Endpoint
B20: api/departments | I20: O | J20: O | K20: O | L20: O
B21: api/departments/{id} | F21: O | G21: O | H21: O | M21: O | N21: O | O21: O | P21: O | Q21: O | R21: O | S21: O | T21: O
B22: Input
B23: id
D24: {guid} | F24: O | H24: O | M24: O | Q24: O | R24: O | S24: O
B25: non-existed {guid} | G25: O | P25: O | T25: O
D26: "abc" | N26: O | O26: O
B27: code
D28: {null} | J28: O | N28: O | P28: O
D29: "DEP_IT" | I29: O | K29: O | M29: O | O29: O
C30: "DEP_STUDENT_SERVICE" | L30: O | Q30: O
B31: name
D32: {null} | M32: O | Q32: O
D33: "Phòng IT" | I33: O | J33: O | K33: O | L33: O | N33: O | O33: O | P33: O
B34: description
D35: {null} | I35: O | M35: O | N35: O | P35: O | Q35: O
B36: "Profession in supporting IT proplems" | J36: O | K36: O | L36: O | O36: O
A39: Confirm | B39: Return
D40: 200: Successfully get 1 record with the id {id} | F40: O
D41: 200: Create successfully | I41: O
D42: 200: Update successfully | M42: O
D43: 200: Dekete successfully | R43: O
D44: 400: Bad Request | G44: O | H44: O | J44: O | K44: O | L44: O | N44: O | P44: O | Q44: O | T44: O
...

Sheet FE-12
A2: Function Code | C2: FE-12 | F2: Function Name | L2: FE-12_View list of classrooms
A3: Created By | C3: BaoPG | F3: Executed By | L3: BaoPG
A4: Lines of code | C4: 100 | F4: Lack of test cases | L4: =IF(Functions!E6<>"N/A",SUM(C4*Functions!E6/1000,-O7),"N/A") -> -7
A5: Test requirement | C5: N/A
A6: Passed | C6: Failed | F6: Untested | L6: N/A/B | O6: Total Test Cases
A7: =COUNTIF(F48:HQ48,"P") -> 9 | C7: =COUNTIF(F48:HQ48,"F") -> 0 | F7: =SUM(O7,-A7,-C7) -> 0 | L7: =COUNTIF(E47:HQ47,"N") -> 6 | M7: =COUNTIF(E47:HQ47,"A") -> 3 | N7: =COUNTIF(E47:HQ47,"B") -> 0 | O7: =COUNTA(E9:HT9) -> 9
F9: UTCID01 | G9: UTCID02 | H9: UTCID03 | I9: UTCID04 | J9: UTCID05 | K9: UTCID06 | L9: UTCID07 | M9: UTCID08 | N9: UTCID09
A10: Condition | B10: Precondition
D11: Authorized | F11: O | G11: O | H11: O | I11: O | J11: O | K11: O | L11: O | N11: O
D12: At least 1 rooms records in the database | F12: O | G12: O | H12: O | I12: O | J12: O | K12: O | L12: O | M12: O
B14: HTTP Method
D15: GET | F15: O | G15: O | H15: O | I15: O | J15: O | K15: O | L15: O | M15: O | N15: O
B16: API Endpoint
B17: api/rooms | F17: O | M17: O
B18: api/rooms?PageNumber=0&PageSize=20 | G18: O | N18: O
B19: api/room?name=Alpha | H19: O
B20: api/room?building=2 | I20: O
B21: api/rooms/?SortBy=Name&SortOrder=1 | J21: O
B22: api/room?search=201 | K22: O
D24: api/rooms?PageNumber=0&PageSize=abcd | L24: O
A28: Confirm | B28: Return
D29: 200: Success with 10 records | F29: O
D30: 200: Success with 20 records | G30: O
D31: 200: Success with records have name = Alpha | H31: O
D32: 200: Success with records have building = Gamma | I32: O
D33: 200: Success with 10 records is sorted | J33: O
D34: 200: Success with records have word "201" | K34: O
D35: 400: Bad Request | L35: O
D36: 403: No Permision | M36: O
D37: 404 : Not Found | N37: O
B39: Exception
B41: Log message
D42: "Get List of Rooms successfully" | F42: O | G42: O | H42: O | I42: O | J42: O | K42: O
D43: "List of Rooms not found" | N43: O
D44: "Invalid request parameters for getting list of rooms" | L44: O
D45: "User does not have permission to access the list of rooms" | M45: O
A47: Result | B47: Type(N : Normal, A : Abnormal, B : Boundary) | F47: N | G47: N | H47: N | I47: N | J47: N | K47: N | L47: A | M47: A | N47: A
B48: Passed/Failed | F48: P | G48: P | H48: P | I48: P | J48: P | K48: P | L48: P | M48: P | N48: P
B49: Executed Date | F49: 45721 | G49: 45721 | H49: 45721 | I49: 45721 | J49: 45721 | K49: 39143 | L49: 39144 | M49: 39145 | N49: 45390
B50: Defect ID

Sheet FE-13
A2: Function Code | C2: FE-13 | F2: Function Name | L2: FE-13_CRUD classroom
A3: Created By | C3: BaoPG | F3: Executed By | L3: BaoPG
A4: Lines of code | C4: 100 | F4: Lack of test cases | L4: =IF(Functions!E6<>"N/A",SUM(C4*Functions!E6/1000,-O7),"N/A") -> -15
A5: Test requirement | C5: N/A
A6: Passed | C6: Failed | F6: Untested | L6: N/A/B | O6: Total Test Cases
A7: =COUNTIF(F68:HU68,"P") -> 17 | C7: =COUNTIF(F68:HU68,"F") -> 0 | F7: =SUM(O7,-A7,-C7) -> 0 | L7: =COUNTIF(E67:HU67,"N") -> 4 | M7: =COUNTIF(E67:HU67,"A") -> 13 | N7: =COUNTIF(E67:HU67,"B") -> 0 | O7: =COUNTA(E9:HX9) -> 17
F9: UTCID01 | G9: UTCID02 | H9: UTCID03 | I9: UTCID04 | J9: UTCID05 | K9: UTCID06 | L9: UTCID07 | M9: UTCID08 | N9: UTCID09 | O9: UTCID10 | P9: UTCID11 | Q9: UTCID12 | R9: UTCID13 | S9: UTCID14 | T9: UTCID15 | U9: UTCID16 | V9: UTCID17
A10: Condition | B10: Precondition
D11: Authorized | F11: O | G11: O | I11: O | J11: O | K11: O | L11: O | N11: O | O11: O | P11: O | R11: O | S11: O | T11: O | V11: O
D12: Classroom is already exist | F12: O | G12: O | H12: O | N12: O | O12: O | P12: O | Q12: O | S12: O | T12: O | U12: O
D13: Classroom is not exist | I13: O | J13: O | K13: O | L13: O | M13: O | R13: O | V13: O
D14: Classroom "Gamma 202" is already exist | S14: O
B15: HTTP Method
D16: GET | F16: O | G16: O | H16: O | I16: O
D17: POST | J17: O | K17: O | L17: O | M17: O | N17: O
D18: PATCH | O18: O | P18: O | Q18: O | R18: O | S18: O
D19: DELETE | T19: O | U19: O | V19: O
B20: API Endpoint
B21: api/rooms/:id | F21: O | G21: O | H21: O | I21: O | O21: O | Q21: O | R21: O | S21: O | T21: O | U21: O | V21: O
B22: api/rooms | J22: O | K22: O | L22: O | M22: O | N22: O
B24: Input
B25: id
B26: {guid} | F26: O | H26: O | I26: O | O26: O | Q26: O | R26: O | S26: O | T26: O | U26: O | V26: O
B27: abc | G27: O | P27: O
B28: name
D29: Gamma 201 | J29: O | L29: O | M29: O | N29: O | O29: O | P29: O | Q29: O | R29: O
D30: Gamma 1234567890 | K30: O
D31: Gamma 202 | S31: O
B32: building
D33: 2 | J33: O | K33: O | M33: O | N33: O | O33: O | P33: O | Q33: O | R33: O | S33: O
D34: gamma | L34: O
A36: Confirm | B36: Return
D37: 200: Success with 1 record have {id} | F37: O
D38: 200: Success | O38: O | T38: O
D39: 201: Created | J39: O
D40: 400: Bad Request | G40: O | K40: O | L40: O | P40: O
D41: 403: No Permision | H41: O | M41: O | Q41: O | U41: O
D42: 404 : Not Found | I42: O | R42: O | V42: O
D43: 409: Conflict | N43: O | S43: O
B44: Exception
...

Sheet FE-14
A2: Function Code | C2: FE-14 | F2: Function Name | L2: FE-14_Import classroom via excel file
A3: Created By | C3: TuanND | F3: Executed By | L3: QuangTVD
A4: Lines of code | C4: 100 | F4: Lack of test cases | L4: =IF(Functions!E6<>"N/A",SUM(C4*Functions!E6/1000,-O7),"N/A") -> -1
A5: Test requirement | C5: N/A
A6: Passed | C6: Failed | F6: Untested | L6: N/A/B | O6: Total Test Cases
A7: =COUNTIF(F31:HQ31,"P") -> 3 | C7: =COUNTIF(F31:HQ31,"F") -> 0 | F7: =SUM(O7,-A7,-C7) -> 0 | L7: =COUNTIF(E30:HQ30,"N") -> 1 | M7: =COUNTIF(E30:HQ30,"A") -> 2 | N7: =COUNTIF(E30:HQ30,"B") -> 0 | O7: =COUNTA(E9:HT9) -> 3
F9: UTCID01 | G9: UTCID02 | H9: UTCID03
A10: Condition | B10: Precondition
D11: Authorized | F11: O | G11: O
B13: HTTP Method
D14: POST | F14: O | G14: O | H14: O
B15: API Endpoint
D16: /api/rooms/import | F16: O | G16: O | H16: O
B17: Input
B18: file
D19: Imported file follows the template | F19: O | H19: O
D20: Imported file does not follow the template | G20: O
A22: Confirm | B22: Return
D23: 200 Success | F23: O
D24: 400 Bad request | G24: O
D25: 401 Unauthorized | H25: O
B26: Log message
D27: Import successfully | F27: O
D28: Import failed: Invalid import file | G28: O
D29: Invalid authorization | H29: O
A30: Result | B30: Type(N : Normal, A : Abnormal, B : Boundary) | F30: N | G30: A | H30: A
B31: Passed/Failed | F31: P | G31: P | H31: P
B32: Executed Date | F32: 45757 | G32: 45757 | H32: 45757
B33: Defect ID

Sheet FE-15
A2: Function Code | C2: FE-15 | E2: Function Name | K2: FE-15_View list of students
A3: Created By | C3: TuanND | E3: Executed By | K3: TuanND
A4: Lines of code | C4: 100 | E4: Lack of test cases
A5: Test requirement | C5: N/A
A6: Passed | C6: Failed | E6: Untested | K6: N/A/B | N6: Total Test Cases
A7: =COUNTIF(E47:HP47,"P") -> 9 | C7: =COUNTIF(E47:HP47,"F") -> 0 | E7: =SUM(N7,-A7,-C7) -> 0 | K7: 6 | L7: 3 | M7: =COUNTIF(E35:HP35,"B") -> 0 | N7: =COUNTA(E9:HS9) -> 9
E9: UTCID01 | F9: UTCID02 | G9: UTCID03 | H9: UTCID04 | I9: UTCID05 | J9: UTCID06 | K9: UTCID07 | L9: UTCID08 | M9: UTCID09
A10: Condition | B10: Precondition
D11: Authorized | E11: O | F11: O | G11: O | H11: O | I11: O | J11: O | K11: O | M11: O
D12: At least 1 students records in the database | E12: O | F12: O | G12: O | H12: O | I12: O | J12: O | K12: O | L12: O
B14: HTTP Method
D15: GET | E15: O | F15: O | G15: O | H15: O | I15: O | J15: O | K15: O | L15: O | M15: O
B16: API Endpoint
B17: api/students | E17: O | L17: O
B18: api/students?PageNumber=0&PageSize=20 | F18: O | M18: O
B19: api/student?name=Alpha | G19: O
B20: api/student?building=2 | H20: O
B21: api/students/?SortBy=Name&SortOrder=1 | I21: O
B22: api/student?search=201 | J22: O
D23: api/students?PageNumber=0&PageSize=abcd | K23: O
A27: Confirm | B27: Return
D28: 200: Success with 10 records | E28: O
D29: 200: Success with 20 records | F29: O
D30: 200: Success with records have name = "Nguyễn Đình Tuấn" | G30: O
D31: 200: Success with records have code = DE170076 | H31: O
D32: 200: Success with 10 records is sorted | I32: O
D33: 200: Success with records have word "201" | J33: O
D34: 400: Bad Request | K34: O
D35: 403: No Permision | L35: O
D36: 404 : Not Found | M36: O
B38: Exception
B40: Log message
D41: "Get List of students successfully" | E41: O | F41: O | G41: O | H41: O | I41: O | J41: O
D42: "List of students not found" | M42: O
D43: "Invalid request parameters for getting list of students" | K43: O
D44: "User does not have permission to access the list of students" | L44: O
A46: Result | B46: Type(N : Normal, A : Abnormal, B : Boundary) | E46: N | F46: N | G46: N | H46: N | I46: N | J46: N | K46: A | L46: A | M46: A
B47: Passed/Failed | E47: P | F47: P | G47: P | H47: P | I47: P | J47: P | K47: P | L47: P | M47: P
B48: Executed Date | E48: 45721 | F48: 45721 | G48: 45721 | H48: 45721 | I48: 45721 | J48: 39143 | K48: 39144 | L48: 39145 | M48: 45390
B49: Defect ID

Sheet FE-16
A2: Function Code | C2: FE-16 | E2: Function Name | K2: FE-16_CRUD Student
A3: Created By | C3: TuanND | E3: Executed By | K3: TuanND
A4: Lines of code | C4: 100 | E4: Lack of test cases | K4: =IF(Functions!E6<>"N/A",SUM(C4*Functions!E6/1000,-N7),"N/A") -> -15
A5: Test requirement | C5: N/A
A6: Passed | C6: Failed | E6: Untested | K6: N/A/B | N6: Total Test Cases
A7: =COUNTIF(E65:HT65,"P") -> 17 | C7: =COUNTIF(E65:HT65,"F") -> 0 | E7: =SUM(N7,-A7,-C7) -> 0 | K7: =COUNTIF(E64:HT64,"N") -> 4 | L7: =COUNTIF(E64:HT64,"A") -> 13 | M7: =COUNTIF(E64:HT64,"B") -> 0 | N7: =COUNTA(E9:HW9) -> 17
E9: UTCID01 | F9: UTCID02 | G9: UTCID03 | H9: UTCID04 | I9: UTCID05 | J9: UTCID06 | K9: UTCID07 | L9: UTCID08 | M9: UTCID09 | N9: UTCID10 | O9: UTCID11 | P9: UTCID12 | Q9: UTCID13 | R9: UTCID14 | S9: UTCID15 | T9: UTCID16 | U9: UTCID17
A10: Condition | B10: Precondition
D11: Authorized | E11: O | F11: O | H11: O | I11: O | J11: O | K11: O | M11: O | N11: O | O11: O | Q11: O | R11: O | S11: O | U11: O
D12: student is already exist | E12: O | F12: O | G12: O | M12: O | N12: O | O12: O | P12: O | R12: O | S12: O | T12: O
D13: student is not exist | H13: O | I13: O | J13: O | K13: O | L13: O | Q13: O | U13: O
D14: student "de170076" is already exist | R14: O
B15: HTTP Method
D16: GET | E16: O | F16: O | G16: O | H16: O
D17: POST | I17: O | J17: O | K17: O | L17: O | M17: O
D18: PATCH | N18: O | O18: O | P18: O | Q18: O | R18: O
D19: DELETE | S19: O | T19: O | U19: O
B20: API Endpoint
B21: api/students/:id | E21: O | F21: O | G21: O | H21: O | N21: O | P21: O | Q21: O | R21: O | S21: O | T21: O | U21: O
B22: api/students | I22: O | J22: O | K22: O | L22: O | M22: O
B24: Input
B25: id
B26: {guid} | E26: O | G26: O | H26: O | N26: O | P26: O | Q26: O | R26: O | S26: O | T26: O | U26: O
B27: abc | F27: O | O27: O
B28: code
D29: de170076 | I29: O | K29: O | L29: O | M29: O | N29: O | O29: O | P29: O | Q29: O
D30: de99999 | J30: O
D31: de10 | R31: O
A33: Confirm | B33: Return
D34: 200: Success with 1 record have {id} | E34: O
D35: 200: Success | N35: O | S35: O
D36: 201: Created | I36: O
D37: 400: Bad Request | F37: O | J37: O | K37: O | O37: O
D38: 403: No Permision | G38: O | L38: O | P38: O | T38: O
D39: 404 : Not Found | H39: O | Q39: O | U39: O
D40: 409: Conflict | M40: O | R40: O
B41: Exception
B43: Log message
D44: "Student created successfully" | I44: O
D45: "Failed to create student: Invalid request parameters" | J45: O | K45: O
...

Sheet FE-17
A2: Function Code | C2: FE-17 | F2: Function Name | L2: FE-17_Import students via excel file
A3: Created By | C3: TuanND | F3: Executed By | L3: TuanND
A4: Lines of code | C4: 100 | F4: Lack of test cases | L4: =IF(Functions!E6<>"N/A",SUM(C4*Functions!E6/1000,-O7),"N/A") -> -1
A5: Test requirement | C5: N/A
A6: Passed | C6: Failed | F6: Untested | L6: N/A/B | O6: Total Test Cases
A7: =COUNTIF(F31:HQ31,"P") -> 3 | C7: =COUNTIF(F31:HQ31,"F") -> 0 | F7: =SUM(O7,-A7,-C7) -> 0 | L7: =COUNTIF(E30:HQ30,"N") -> 1 | M7: =COUNTIF(E30:HQ30,"A") -> 2 | N7: =COUNTIF(E30:HQ30,"B") -> 0 | O7: =COUNTA(E9:HT9) -> 3
F9: UTCID01 | G9: UTCID02 | H9: UTCID03
A10: Condition | B10: Precondition
D11: Authorized | F11: O | G11: O
B13: HTTP Method
D14: POST | F14: O | G14: O | H14: O
B15: API Endpoint
D16: /api/students/import | F16: O | G16: O | H16: O
B17: Input
B18: file
D19: Imported file follows the template | F19: O | H19: O
D20: Imported file does not follow the template | G20: O
A22: Confirm | B22: Return
D23: 200 Success | F23: O
D24: 400 Bad request | G24: O
D25: 401 Unauthorized | H25: O
B26: Log message
D27: Import successfully | F27: O
D28: Import failed: Invalid import file | G28: O
D29: Invalid authorization | H29: O
A30: Result | B30: Type(N : Normal, A : Abnormal, B : Boundary) | F30: N | G30: A | H30: A
B31: Passed/Failed | F31: P | G31: P | H31: P
B32: Executed Date | F32: 45757 | G32: 45757 | H32: 45757
B33: Defect ID

Sheet FE-18
A2: Function Code | C2: FE-18 | E2: Function Name | K2: FE-18_View list of subjects
A3: Created By | C3: TuanND | E3: Executed By | K3: TuanND
A4: Lines of code | C4: 100 | E4: Lack of test cases
A5: Test requirement | C5: N/A
A6: Passed | C6: Failed | E6: Untested | K6: N/A/B | N6: Total Test Cases
A7: =COUNTIF(E47:HP47,"P") -> 9 | C7: =COUNTIF(E47:HP47,"F") -> 0 | E7: =SUM(N7,-A7,-C7) -> 0 | K7: 6 | L7: 3 | M7: =COUNTIF(E35:HP35,"B") -> 0 | N7: =COUNTA(E9:HS9) -> 9
E9: UTCID01 | F9: UTCID02 | G9: UTCID03 | H9: UTCID04 | I9: UTCID05 | J9: UTCID06 | K9: UTCID07 | L9: UTCID08 | M9: UTCID09
A10: Condition | B10: Precondition
D11: Authorized | E11: O | F11: O | G11: O | H11: O | I11: O | J11: O | K11: O | M11: O
D12: At least 1 courses records in the database | E12: O | F12: O | G12: O | H12: O | I12: O | J12: O | K12: O | L12: O
B14: HTTP Method
D15: GET | E15: O | F15: O | G15: O | H15: O | I15: O | J15: O | K15: O | L15: O | M15: O
B16: API Endpoint
B17: api/courses | E17: O | L17: O
B18: api/courses?PageNumber=0&PageSize=20 | F18: O | M18: O
B19: api/course?name=Alpha | G19: O
B20: api/course?building=2 | H20: O
B21: api/courses/?SortBy=Name&SortOrder=1 | I21: O
B22: api/course?search=201 | J22: O
D23: api/courses?PageNumber=0&PageSize=abcd | K23: O
A27: Confirm | B27: Return
D28: 200: Success with 10 records | E28: O
D29: 200: Success with 20 records | F29: O
D30: 200: Success with records have name = "Toán cao cấp" | G30: O
D31: 200: Success with records have code = MAE101 | H31: O
D32: 200: Success with 10 records is sorted | I32: O
D33: 200: Success with records have word "201" | J33: O
D34: 400: Bad Request | K34: O
D35: 403: No Permision | L35: O
D36: 404 : Not Found | M36: O
B38: Exception
B40: Log message
D41: "Get List of courses successfully" | E41: O | F41: O | G41: O | H41: O | I41: O | J41: O
D42: "List of courses not found" | M42: O
D43: "Invalid request parameters for getting list of courses" | K43: O
D44: "User does not have permission to access the list of courses" | L44: O
A46: Result | B46: Type(N : Normal, A : Abnormal, B : Boundary) | E46: N | F46: N | G46: N | H46: N | I46: N | J46: N | K46: A | L46: A | M46: A
B47: Passed/Failed | E47: P | F47: P | G47: P | H47: P | I47: P | J47: P | K47: P | L47: P | M47: P
B48: Executed Date | E48: 45721 | F48: 45721 | G48: 45721 | H48: 45721 | I48: 45721 | J48: 39143 | K48: 39144 | L48: 39145 | M48: 45390
B49: Defect ID

Sheet FE-19
A2: Function Code | C2: FE-19 | E2: Function Name | K2: FE-19_CRUD subjects
A3: Created By | C3: TuanND | E3: Executed By | K3: TuanND
A4: Lines of code | C4: 100 | E4: Lack of test cases | K4: =IF(Functions!E6<>"N/A",SUM(C4*Functions!E6/1000,-N7),"N/A") -> -15
A5: Test requirement | C5: N/A
A6: Passed | C6: Failed | E6: Untested | K6: N/A/B | N6: Total Test Cases
A7: =COUNTIF(E65:HT65,"P") -> 17 | C7: =COUNTIF(E65:HT65,"F") -> 0 | E7: =SUM(N7,-A7,-C7) -> 0 | K7: =COUNTIF(E64:HT64,"N") -> 4 | L7: =COUNTIF(E64:HT64,"A") -> 13 | M7: =COUNTIF(E64:HT64,"B") -> 0 | N7: =COUNTA(E9:HW9) -> 17
E9: UTCID01 | F9: UTCID02 | G9: UTCID03 | H9: UTCID04 | I9: UTCID05 | J9: UTCID06 | K9: UTCID07 | L9: UTCID08 | M9: UTCID09 | N9: UTCID10 | O9: UTCID11 | P9: UTCID12 | Q9: UTCID13 | R9: UTCID14 | S9: UTCID15 | T9: UTCID16 | U9: UTCID17
A10: Condition | B10: Precondition
D11: Authorized | E11: O | F11: O | H11: O | I11: O | J11: O | K11: O | M11: O | N11: O | O11: O | Q11: O | R11: O | S11: O | U11: O
D12: course is already exist | E12: O | F12: O | G12: O | M12: O | N12: O | O12: O | P12: O | R12: O | S12: O | T12: O
D13: course is not exist | H13: O | I13: O | J13: O | K13: O | L13: O | Q13: O | U13: O
D14: course "MAE101" is already exist | R14: O
B15: HTTP Method
D16: GET | E16: O | F16: O | G16: O | H16: O
D17: POST | I17: O | J17: O | K17: O | L17: O | M17: O
D18: PATCH | N18: O | O18: O | P18: O | Q18: O | R18: O
D19: DELETE | S19: O | T19: O | U19: O
B20: API Endpoint
B21: api/courses/:id | E21: O | F21: O | G21: O | H21: O | N21: O | P21: O | Q21: O | R21: O | S21: O | T21: O | U21: O
B22: api/courses | I22: O | J22: O | K22: O | L22: O | M22: O
B24: Input
B25: id
B26: {guid} | E26: O | G26: O | H26: O | N26: O | P26: O | Q26: O | R26: O | S26: O | T26: O | U26: O
B27: abc | F27: O | O27: O
B28: code
D29: MAE101 | I29: O | K29: O | L29: O | M29: O | N29: O | O29: O | P29: O | Q29: O
D30: MAE101 00000 | J30: O
D31: MAE102 | R31: O
A33: Confirm | B33: Return
D34: 200: Success with 1 record have {id} | E34: O
D35: 200: Success | N35: O | S35: O
D36: 201: Created | I36: O
D37: 400: Bad Request | F37: O | J37: O | K37: O | O37: O
D38: 403: No Permision | G38: O | L38: O | P38: O | T38: O
D39: 404 : Not Found | H39: O | Q39: O | U39: O
D40: 409: Conflict | M40: O | R40: O
B41: Exception
B43: Log message
D44: "Course created successfully" | I44: O
D45: "Failed to create course: Invalid request parameters" | J45: O | K45: O
...

Sheet FE-20
A2: Function Code | C2: FE-20 | F2: Function Name | L2: FE-20_Import subjects via excel file
A3: Created By | C3: TuanND | F3: Executed By | L3: TuanND
